C:\Users\Man\AppData\Local\Packages\PythonSoftwareFoundation.Python.3.13_qbz5n2kfra8p0\LocalCache\local-packages\Python313\site-packages\_pytest\config\__init__.py:331: PluggyTeardownRaisedWarning: A plugin raised an exception during an old-style hookwrapper teardown.
Plugin: helpconfig, Hook: pytest_cmdline_parse
UsageError: C:\Users\Man\ultra\projects\karen\pytest.ini:38: unexpected line: ']'
For more information see https://pluggy.readthedocs.io/en/stable/api_reference.html#pluggy.PluggyTeardownRaisedWarning
  config = pluginmanager.hook.pytest_cmdline_parse(
ERROR: C:\Users\Man\ultra\projects\karen\pytest.ini:38: unexpected line: ']'

